<?xml version="1.0" encoding="utf-8"?>
<!-- This URDF was automatically created by SolidWorks to URDF Exporter! Originally created by Stephen Brawner (brawner@gmail.com) 
     Commit Version: 1.6.0-1-g15f4949  Build Version: 1.6.7594.29634
     For more information, please see http://wiki.ros.org/sw_urdf_exporter -->
<robot
  name="mobile_robot">
  <link
    name="base_link">
    <inertial>
      <origin
        xyz="-1.0265E-18 -5.1424E-18 0.005"
        rpy="0 0 0" />
      <mass
        value="0.20628" />
      <inertia
        ixx="0.0001912"
        ixy="5.3767E-20"
        ixz="-2.1198E-21"
        iyy="0.00070862"
        iyz="-7.5549E-22"
        izz="0.00089641" />
    </inertial>
    <visual>
      <origin
        xyz="0 0 0"
        rpy="0 0 0" />
      <geometry>
        <mesh
          filename="package://mobile_robot/meshes/base_link.STL" />
      </geometry>
      <material
        name="">
        <color
          rgba="0.8 0 0 1" />
      </material>
    </visual>
    <collision>
      <origin
        xyz="0 0 0"
        rpy="0 0 0" />
      <geometry>
        <mesh
          filename="package://mobile_robot/meshes/base_link.STL" />
      </geometry>
    </collision>
  </link>
  <link
    name="FL_link">
    <inertial>
      <origin
        xyz="0 -3.4694E-18 0.005"
        rpy="0 0 0" />
      <mass
        value="0.011471" />
      <inertia
        ixx="1.2868E-06"
        ixy="2.6334E-22"
        ixz="1.6168E-23"
        iyy="1.2868E-06"
        iyz="-1.1491E-23"
        izz="2.3824E-06" />
    </inertial>
    <visual>
      <origin
        xyz="0 0 0"
        rpy="0 0 0" />
      <geometry>
        <mesh
          filename="package://mobile_robot/meshes/FL_link.STL" />
      </geometry>
      <material
        name="">
        <color
          rgba="0.79216 0.81961 0.93333 1" />
      </material>
    </visual>
    <collision>
      <origin
        xyz="0 0 0"
        rpy="0 0 0" />
      <geometry>
        <mesh
          filename="package://mobile_robot/meshes/FL_link.STL" />
      </geometry>
    </collision>
  </link>
  <joint
    name="FL_Jnt"
    type="continuous">
    <origin
      xyz="0.08 0.06 0.005"
      rpy="1.5708 0 3.1416" />
    <parent
      link="base_link" />
    <child
      link="FL_link" />
    <axis
      xyz="0 0 1" />
    <limit
      lower="0"
      upper="0"
      effort="0"
      velocity="0" />
  </joint>
  <link
    name="FR_Link">
    <inertial>
      <origin
        xyz="0 -8.6736E-19 -0.005"
        rpy="0 0 0" />
      <mass
        value="0.011471" />
      <inertia
        ixx="1.2868E-06"
        ixy="1.8741E-22"
        ixz="1.1862E-23"
        iyy="1.2868E-06"
        iyz="7.876E-25"
        izz="2.3824E-06" />
    </inertial>
    <visual>
      <origin
        xyz="0 0 0"
        rpy="0 0 0" />
      <geometry>
        <mesh
          filename="package://mobile_robot/meshes/FR_Link.STL" />
      </geometry>
      <material
        name="">
        <color
          rgba="0.79216 0.81961 0.93333 1" />
      </material>
    </visual>
    <collision>
      <origin
        xyz="0 0 0"
        rpy="0 0 0" />
      <geometry>
        <mesh
          filename="package://mobile_robot/meshes/FR_Link.STL" />
      </geometry>
    </collision>
  </link>
  <joint
    name="FR_Jnt"
    type="continuous">
    <origin
      xyz="0.08 -0.06 0.005"
      rpy="1.5708 0 3.1416" />
    <parent
      link="base_link" />
    <child
      link="FR_Link" />
    <axis
      xyz="0 0 -1" />
    <limit
      lower="0"
      upper="0"
      effort="0"
      velocity="0" />
  </joint>
  <link
    name="BL_Link">
    <inertial>
      <origin
        xyz="1.3878E-17 -1.7347E-18 0.005"
        rpy="0 0 0" />
      <mass
        value="0.011471" />
      <inertia
        ixx="1.2868E-06"
        ixy="2.8757E-22"
        ixz="9.0271E-24"
        iyy="1.2868E-06"
        iyz="-1.1249E-23"
        izz="2.3824E-06" />
    </inertial>
    <visual>
      <origin
        xyz="0 0 0"
        rpy="0 0 0" />
      <geometry>
        <mesh
          filename="package://mobile_robot/meshes/BL_Link.STL" />
      </geometry>
      <material
        name="">
        <color
          rgba="0.79216 0.81961 0.93333 1" />
      </material>
    </visual>
    <collision>
      <origin
        xyz="0 0 0"
        rpy="0 0 0" />
      <geometry>
        <mesh
          filename="package://mobile_robot/meshes/BL_Link.STL" />
      </geometry>
    </collision>
  </link>
  <joint
    name="BL_Jnt"
    type="continuous">
    <origin
      xyz="-0.08 0.06 0.005"
      rpy="1.5708 0 3.1416" />
    <parent
      link="base_link" />
    <child
      link="BL_Link" />
    <axis
      xyz="0 0 1" />
    <limit
      lower="0"
      upper="0"
      effort="0"
      velocity="0" />
  </joint>
  <link
    name="BR_Link">
    <inertial>
      <origin
        xyz="5.5511E-17 2.0817E-17 -0.005"
        rpy="0 0 0" />
      <mass
        value="0.011471" />
      <inertia
        ixx="1.2868E-06"
        ixy="4.2352E-22"
        ixz="8.6885E-24"
        iyy="1.2868E-06"
        iyz="7.6204E-24"
        izz="2.3824E-06" />
    </inertial>
    <visual>
      <origin
        xyz="0 0 0"
        rpy="0 0 0" />
      <geometry>
        <mesh
          filename="package://mobile_robot/meshes/BR_Link.STL" />
      </geometry>
      <material
        name="">
        <color
          rgba="0.79216 0.81961 0.93333 1" />
      </material>
    </visual>
    <collision>
      <origin
        xyz="0 0 0"
        rpy="0 0 0" />
      <geometry>
        <mesh
          filename="package://mobile_robot/meshes/BR_Link.STL" />
      </geometry>
    </collision>
  </link>
  <joint
    name="BR_Jnt"
    type="continuous">
    <origin
      xyz="-0.08 -0.06 0.005"
      rpy="1.5708 0.55203 3.1416" />
    <parent
      link="base_link" />
    <child
      link="BR_Link" />
    <axis
      xyz="0 0 -1" />
    <limit
      lower="0"
      upper="0"
      effort="0"
      velocity="0" />
  </joint>

<gazebo>
  <plugin name="differential_drive_controller" filename="libgazebo_ros_diff_drive.so">

    <!-- Plugin update rate in Hz -->
    <updateRate>100</updateRate>

    <!-- Name of left joint, defaults to `left_joint` -->
    <leftJoint>FL_Jnt</leftJoint>

    <!-- Name of right joint, defaults to `right_joint` -->
    <rightJoint>FR_Jnt</rightJoint>

    <!-- The distance from the center of one wheel to the other, in meters, defaults to 0.34 m -->
    <!-- <wheelSeparation>0.5380</wheelSeparation> -->

    <!-- Diameter of the wheels, in meters, defaults to 0.15 m -->
    <!-- <wheelDiameter>0.2410</wheelDiameter> -->

    <!-- Wheel acceleration, in rad/s^2, defaults to 0.0 rad/s^2 -->
    <wheelAcceleration>1.0</wheelAcceleration>

    <!-- Maximum torque which the wheels can produce, in Nm, defaults to 5 Nm -->
    <wheelTorque>20</wheelTorque>

    <!-- Topic to receive geometry_msgs/Twist message commands, defaults to `cmd_vel` -->
    <commandTopic>cmd_vel</commandTopic>

    <!-- Topic to publish nav_msgs/Odometry messages, defaults to `odom` -->
    <odometryTopic>odom</odometryTopic>

    <!-- Odometry frame, defaults to `odom` -->
    <odometryFrame>odom</odometryFrame>

    <!-- Robot frame to calculate odometry from, defaults to `base_footprint` -->
    <robotBaseFrame>base_footprint</robotBaseFrame>

    <!-- Odometry source, 0 for ENCODER, 1 for WORLD, defaults to WORLD -->
    <odometrySource>1</odometrySource>

    <!-- Set to true to publish transforms for the wheel links, defaults to false -->
    <publishWheelTF>true</publishWheelTF>

    <!-- Set to true to publish transforms for the odometry, defaults to true -->
    <publishOdom>true</publishOdom>

    <!-- Set to true to publish sensor_msgs/JointState on /joint_states for the wheel joints, defaults to false -->
    <publishWheelJointState>true</publishWheelJointState>

    <!-- Set to true to swap right and left wheels, defaults to true -->
    <legacyMode>false</legacyMode>
  </plugin>
</gazebo>

<gazebo>
  <plugin name="differential_drive_controller" filename="libgazebo_ros_diff_drive.so">

    <!-- Plugin update rate in Hz -->
    <updateRate>100</updateRate>

    <!-- Name of left joint, defaults to `left_joint` -->
    <leftJoint>BL_Jnt</leftJoint>

    <!-- Name of right joint, defaults to `right_joint` -->
    <rightJoint>BR_Jnt</rightJoint>

    <!-- The distance from the center of one wheel to the other, in meters, defaults to 0.34 m -->
    <!-- <wheelSeparation>0.5380</wheelSeparation> -->

    <!-- Diameter of the wheels, in meters, defaults to 0.15 m -->
    <!-- <wheelDiameter>0.2410</wheelDiameter> -->

    <!-- Wheel acceleration, in rad/s^2, defaults to 0.0 rad/s^2 -->
    <wheelAcceleration>1.0</wheelAcceleration>

    <!-- Maximum torque which the wheels can produce, in Nm, defaults to 5 Nm -->
    <wheelTorque>20</wheelTorque>

    <!-- Topic to receive geometry_msgs/Twist message commands, defaults to `cmd_vel` -->
    <commandTopic>cmd_vel</commandTopic>

    <!-- Topic to publish nav_msgs/Odometry messages, defaults to `odom` -->
    <odometryTopic>odom</odometryTopic>

    <!-- Odometry frame, defaults to `odom` -->
    <odometryFrame>odom</odometryFrame>

    <!-- Robot frame to calculate odometry from, defaults to `base_footprint` -->
    <robotBaseFrame>base_footprint</robotBaseFrame>

    <!-- Odometry source, 0 for ENCODER, 1 for WORLD, defaults to WORLD -->
    <odometrySource>1</odometrySource>

    <!-- Set to true to publish transforms for the wheel links, defaults to false -->
    <publishWheelTF>true</publishWheelTF>

    <!-- Set to true to publish transforms for the odometry, defaults to true -->
    <publishOdom>true</publishOdom>

    <!-- Set to true to publish sensor_msgs/JointState on /joint_states for the wheel joints, defaults to false -->
    <publishWheelJointState>true</publishWheelJointState>

    <!-- Set to true to swap right and left wheels, defaults to true -->
    <legacyMode>false</legacyMode>
  </plugin>
</gazebo>










</robot>